Workbook

Sheet Salary Sheet
A1: Bin Mishal Global Service Co. Ltd.
A2: Period : May''26
A3: Salary Sheet
A5: SL No | B5: Staff Name | C5: Joining Date | D5: Designation | E5: Kafala Status | F5: Branch Name | G5: Working Days | H5: Absent Days | I5: Present Days | J5: Per Days Salary | K5: O.T Hours | L5: Advance Loan | M5: Earnings | S5: Deduction | X5: Net Salary Amount | Y5: Remaining Loan | Z5: Bank Pay
M6: Basic | N6: House Rent | O6: Food | P6: Commission | Q6: Over Time | R6: Gross Salary | S6: Loan Adjust | T6: Absent Cost | U6: Iqama Cost | V6: Fine | W6: Total Deduction | X6: Payable:
A7: 1 | B7: Md.Afsar Uddin Bhuiyan | C7: 09.05.2025 | D7: Central Manager | E7: Sorikatul BMT | F7: Head Office | G7: 31 | H7: 0 | I7: =G7-H7 -> 31 | J7: =+M7/G7 -> 96.774194 | K7: 0 | L7: 3000 | M7: 3000 | N7: 0 | O7: 0 | P7: 0 | Q7: =J7/12*K7*1.5 -> 0 | R7: =SUM(M7:Q7) -> 3000 | S7: 0 | T7: =+H7*J7 -> 0 | U7: 0 | V7: 0 | W7: =SUM(S7:V7) -> 0 | X7: =+R7-W7-Z7 -> 0 | Y7: =L7-S7 -> 3000 | Z7: 3000 | AA7: 1000SR Pay to DMM | AB7: 200+1200+500+500
A8: 2 | B8: Md.Sana Ullah | C8: 09.03.2025 | D8: Accounts Manager | E8: Under Kafala | F8: Head Office | G8: 31 | H8: 0 | I8: =G8-H8 -> 31 | J8: =+M8/G8 -> 87.096774 | K8: 0 | L8: 1500 | M8: 2700 | N8: 0 | O8: 0 | P8: 0 | Q8: =J8/12*K8*1.5 -> 0 | R8: =SUM(M8:Q8) -> 2700 | S8: 0 | T8: =+H8*J8 -> 0 | U8: 0 | V8: 0 | W8: =SUM(S8:V8) -> 0 | X8: =+R8-W8-Z8 -> 2700 | Y8: =L8-S8 -> 1500 | Z8: 0
A9: 3 | B9: Shahadat Hossain Nishad | C9: 27.03.2026 | D9: Cen-Reservation Exe | E9: Sorikatul BMT | F9: Head Office | G9: 31 | H9: 0 | I9: =G9-H9 -> 31 | J9: =+M9/G9 -> 80.645161 | K9: 0 | L9: 1500 | M9: 2500 | N9: 0 | O9: 0 | P9: 0 | Q9: =J9/12*K9*1.5 -> 0 | R9: =SUM(M9:Q9) -> 2500 | S9: 400 | T9: =+H9*J9 -> 0 | U9: 0 | V9: 0 | W9: =SUM(S9:V9) -> 400 | X9: =+R9-W9-Z9 -> 2100 | Y9: =L9-S9 -> 1100 | Z9: 0 | AA9: Jeyara Passanger
A10: 4 | B10: Md.Ariful Haque | C10: 08.09.2025 | D10: Accounts Sr.Executive | E10: Under Kafala | F10: Head Office | G10: 31 | H10: 0 | I10: =G10-H10 -> 31 | J10: =+M10/G10 -> 58.064516 | K10: 0 | L10: 1800 | M10: 1800 | N10: 0 | O10: 0 | P10: 0 | Q10: =J10/12*K10*1.5 -> 0 | R10: =SUM(M10:Q10) -> 1800 | S10: 1800 | T10: =+H10*J10 -> 0 | U10: 0 | V10: 0 | W10: =SUM(S10:V10) -> 1800 | X10: =+R10-W10-Z10 -> 0 | Y10: =L10-S10 -> 0 | Z10: 0
A11: 5 | B11: Abu Faysal Fahim | C11: 29.08.2025 | D11: Asst.Manager (Audit ) | E11: Under Kafala | F11: Head Office | G11: 31 | H11: 0 | I11: =G11-H11 -> 31 | J11: =+M11/G11 -> 70.967742 | K11: 0 | L11: 6700 | M11: 2200 | N11: 0 | O11: 0 | P11: 0 | Q11: =J11/12*K11*1.5 -> 0 | R11: =SUM(M11:Q11) -> 2200 | S11: 700 | T11: =+H11*J11 -> 0 | U11: 0 | V11: 0 | W11: =SUM(S11:V11) -> 700 | X11: =+R11-W11-Z11 -> 1500 | Y11: =L11-S11 -> 6000 | Z11: 0
A12: 6 | B12: Emon | C12: 09.03.2026 | D12: Social Media Executive | E12: Under Kafala | F12: Head Office | G12: 31 | H12: 0 | I12: =G12-H12 -> 31 | J12: =+M12/G12 -> 64.516129 | K12: 0 | L12: 0 | M12: 2000 | N12: 0 | O12: 0 | P12: 0 | Q12: =J12/12*K12*1.5 -> 0 | R12: =SUM(M12:Q12) -> 2000 | S12: 0 | T12: =+H12*J12 -> 0 | U12: 0 | V12: 0 | W12: =SUM(S12:V12) -> 0 | X12: =+R12-W12-Z12 -> 2000 | Y12: =L12-S12 -> 0 | Z12: 0
A13: 7 | B13: Mohammad Foysal Hossain | C13: 15.01.2024 | D13: PS Of Chairman | E13: Under Kafala | F13: Head Office | G13: 31 | H13: 0 | I13: =G13-H13 -> 31 | J13: =+M13/G13 -> 48.387097 | K13: 0 | L13: 0 | M13: 1500 | N13: 0 | O13: 0 | P13: 0 | Q13: =J13/12*K13*1.5 -> 0 | R13: =SUM(M13:Q13) -> 1500 | S13: 0 | T13: =+H13*J13 -> 0 | U13: 0 | V13: 0 | W13: =SUM(S13:V13) -> 0 | X13: =+R13-W13-Z13 -> 1500 | Y13: =L13-S13 -> 0 | Z13: 0
A14: 8 | B14: Atik Ullah Arif | C14: 07.01.2025 | D14: Ticket Staff | E14: Outside Kafala | F14: Dammam | G14: 31 | H14: 0 | I14: =G14-H14 -> 31 | J14: =+M14/G14 -> 96.774194 | K14: 0 | L14: 0 | M14: 3000 | N14: 0 | O14: 0 | P14: 0 | Q14: =J14/12*K14*1.5 -> 0 | R14: =SUM(M14:Q14) -> 3000 | S14: 0 | T14: =+H14*J14 -> 0 | U14: 0 | V14: 0 | W14: =SUM(S14:V14) -> 0 | X14: =+R14-W14-Z14 -> 3000 | Y14: =L14-S14 -> 0 | Z14: 0
A15: 9 | B15: Kazi Imrul Kayes Aunto | C15: 30.10.2024 | D15: General-Amal Staff | E15: Sorikatul BMT | F15: Dammam | G15: 31 | H15: 0 | I15: =G15-H15 -> 31 | J15: =+M15/G15 -> 67.741935 | K15: 0 | L15: 29769 | M15: 2100 | N15: 0 | O15: 0 | P15: 0 | Q15: =J15/12*K15*1.5 -> 0 | R15: =SUM(M15:Q15) -> 2100 | S15: 1000 | T15: =+H15*J15 -> 0 | U15: 0 | V15: 0 | W15: =SUM(S15:V15) -> 1000 | X15: =+R15-W15-Z15 -> 700 | Y15: =L15-S15 -> 28769 | Z15: 400
A16: 10 | B16: Md.Rakib Hossain | C16: 13.05.2025 | D16: General-Amal Staff | E16: Under Kafala | F16: Dammam | G16: 31 | H16: 0 | I16: =G16-H16 -> 31 | J16: =+M16/G16 -> 48.387097 | K16: 0 | L16: 0 | M16: 1500 | N16: 0 | O16: 0 | P16: 0 | Q16: =J16/12*K16*1.5 -> 0 | R16: =SUM(M16:Q16) -> 1500 | S16: 0 | T16: =+H16*J16 -> 0 | U16: 0 | V16: 0 | W16: =SUM(S16:V16) -> 0 | X16: =+R16-W16-Z16 -> 1500 | Y16: =L16-S16 -> 0 | Z16: 0 | AB16: Total Iqama= | AD16: 304200
A17: 11 | B17: Tahsin Ahmed. | C17: 05.01.2026 | D17: Ticket Staff | E17: Outside Kafala | F17: Dammam | G17: 31 | H17: 0 | I17: =G17-H17 -> 31 | J17: =+M17/G17 -> 64.516129 | K17: 0 | L17: 1925 | M17: 2000 | N17: 0 | O17: 0 | P17: 0 | Q17: =J17/12*K17*1.5 -> 0 | R17: =SUM(M17:Q17) -> 2000 | S17: 225 | T17: =+H17*J17 -> 0 | U17: 0 | V17: 0 | W17: =SUM(S17:V17) -> 225 | X17: =+R17-W17-Z17 -> 1775 | Y17: =L17-S17 -> 1700 | Z17: 0
A18: 12 | B18: Bipul Kumar Mitra. | C18: 01.01.2026 | D18: Cargo Stuff | E18: Outside Kafala | F18: Dammam | G18: 31 | H18: 0 | I18: =G18-H18 -> 31 | J18: =+M18/G18 -> 38.709677 | K18: 0 | L18: 0 | M18: 1200 | N18: 0 | O18: 100 | P18: 0 | Q18: =J18/12*K18*1.5 -> 0 | R18: =SUM(M18:Q18) -> 1300 | S18: 0 | T18: =+H18*J18 -> 0 | U18: 0 | V18: 0 | W18: =SUM(S18:V18) -> 0 | X18: =+R18-W18-Z18 -> 1300 | Y18: =L18-S18 -> 0 | Z18: 0
A19: 13 | B19: Awad Al-Rashidi | C19: 07.01.2027 | D19: Saudi Amel | E19: Outside Kafala | F19: Dammam | G19: 31 | H19: 0 | I19: =G19-H19 -> 31 | J19: =+M19/G19 -> 129.03226 | K19: 0 | L19: 3500 | M19: 4000 | N19: 0 | O19: 0 | P19: 0 | Q19: =J19/12*K19*1.5 -> 0 | R19: =SUM(M19:Q19) -> 4000 | S19: 0 | T19: =+H19*J19 -> 0 | U19: 0 | V19: 0 | W19: =SUM(S19:V19) -> 0 | X19: =+R19-W19-Z19 -> 0 | Y19: =L19-S19 -> 3500 | Z19: 4000
A20: 14 | B20: Etihad | C20: 08.03.2026 | D20: Ticket STAFF | E20: Outside Kafala | F20: Riyadh | G20: 31 | H20: 0 | I20: =G20-H20 -> 31 | J20: =+M20/G20 -> 48.387097 | K20: 0 | L20: 0 | M20: 1500 | N20: 0 | O20: 0 | P20: 0 | Q20: =J20/12*K20*1.5 -> 0 | R20: =SUM(M20:Q20) -> 1500 | S20: 0 | T20: =+H20*J20 -> 0 | U20: 0 | V20: 0 | W20: =SUM(S20:V20) -> 0 | X20: =+R20-W20-Z20 -> 1500 | Z20: 0
A21: 15 | B21: NASIR SAIFELDIN ELNOUR HAG HAMAD | C21: 01.11.2025 | D21: Mowaggep | E21: Outside Kafala | F21: JEDDAH | G21: 31 | H21: 0 | I21: =G21-H21 -> 31 | J21: =+M21/G21 -> 145.16129 | K21: 0 | L21: 0 | M21: 4500 | N21: 0 | O21: 0 | P21: 0 | Q21: =J21/12*K21*1.5 -> 0 | R21: =SUM(M21:Q21) -> 4500 | S21: 0 | T21: =+H21*J21 -> 0 | U21: 0 | V21: 0 | W21: =SUM(S21:V21) -> 0 | X21: =+R21-W21-Z21 -> 4500 | Y21: =L21-S21 -> 0 | Z21: 0
A22: 16 | B22: Esrafil Shodure | C22: 05.03.2024 | D22: General STAFF | E22: Under Kafala | F22: JEDDAH | G22: 31 | H22: 13 | I22: =G22-H22 -> 18 | J22: =+M22/G22 -> 70.967742 | K22: 0 | L22: 1320 | M22: 2200 | N22: 0 | O22: 0 | P22: 0 | Q22: =J22/12*K22*1.5 -> 0 | R22: =SUM(M22:Q22) -> 2200 | S22: 1277 | T22: =+H22*J22 -> 922.58065 | U22: 0 | V22: 0 | W22: =SUM(S22:V22) -> 2199.5806 | X22: =+R22-W22-Z22 -> 0.41935484 | Y22: =L22-S22 -> 43 | Z22: 0
A23: 17 | B23: Ashek Ahmed (Sultan) | C23: 05.07.2024 | D23: Manager | E23: Sorikatul BMT | F23: JEDDAH | G23: 31 | H23: 0 | I23: =G23-H23 -> 31 | J23: =+M23/G23 -> 96.774194 | K23: 0 | L23: 0 | M23: 3000 | N23: 0 | O23: 0 | P23: 0 | Q23: =J23/12*K23*1.5 -> 0 | R23: =SUM(M23:Q23) -> 3000 | S23: 0 | T23: =+H23*J23 -> 0 | U23: 0 | V23: 0 | W23: =SUM(S23:V23) -> 0 | X23: =+R23-W23-Z23 -> 2600 | Y23: =L23-S23 -> 0 | Z23: 400
A24: 18 | B24: Kamruzzaman | C24: 7.12.2025 | D24: Ticket STAFF | E24: Outside Kafala | F24: JEDDAH | G24: 31 | H24: 0 | I24: =G24-H24 -> 31 | J24: =+M24/G24 -> 64.516129 | K24: 0 | L24: 500 | M24: 2000 | N24: 0 | O24: 0 | P24: 0 | Q24: =J24/12*K24*1.5 -> 0 | R24: =SUM(M24:Q24) -> 2000 | S24: 500 | T24: =+H24*J24 -> 0 | U24: 0 | V24: 0 | W24: =SUM(S24:V24) -> 500 | X24: =+R24-W24-Z24 -> 1500 | Y24: =L24-S24 -> 0 | Z24: 0
A25: 19 | B25: Gazi Md.Raduanur Rohman | C25: 23.07.2025 | D25: General STAFF | E25: Outside Kafala | F25: JEDDAH | G25: 31 | H25: 0 | I25: =G25-H25 -> 31 | J25: =+M25/G25 -> 48.387097 | K25: 0 | L25: 0 | M25: 1500 | N25: 0 | O25: 0 | P25: 0 | Q25: =J25/12*K25*1.5 -> 0 | R25: =SUM(M25:Q25) -> 1500 | S25: 0 | T25: =+H25*J25 -> 0 | U25: 0 | V25: 0 | W25: =SUM(S25:V25) -> 0 | X25: =+R25-W25-Z25 -> 1500 | Y25: =L25-S25 -> 0 | Z25: 0
A26: 20 | B26: Md.Khalish Miah | D26: General STAFF | F26: JEDDAH | G26: 31 | H26: 0 | I26: =G26-H26 -> 31 | J26: =+M26/G26 -> 80.645161 | K26: 0 | L26: 2500 | M26: 2500 | N26: 0 | O26: 0 | P26: 0 | Q26: =J26/12*K26*1.5 -> 0 | R26: =SUM(M26:Q26) -> 2500 | S26: 2500 | T26: =+H26*J26 -> 0 | U26: 0 | V26: 0 | W26: =SUM(S26:V26) -> 2500 | X26: =+R26-W26-Z26 -> 0 | Y26: =L26-S26 -> 0 | Z26: 0
A27: 21 | B27: MOHAMMAD SOHEL SHIEKH | C27: 15.11.2023 | D27: Ticket STAFF | E27: Under Kafala | F27: JEDDAH | G27: 31 | H27: 31 | I27: =G27-H27 -> 0 | J27: =+M27/G27 -> 80.645161 | K27: 0 | L27: 190 | M27: 2500 | N27: 0 | O27: 0 | P27: 0 | Q27: =J27/12*K27*1.5 -> 0 | R27: =SUM(M27:Q27) -> 2500 | T27: =+H27*J27 -> 2500 | U27: 0 | V27: 0 | W27: =SUM(S27:V27) -> 2500 | X27: =+R27-W27-Z27 -> 0 | Y27: =L27-S27 -> 190 | Z27: 0
A28: 22 | B28: Rayhan Islam | C28: 23.09.2024 | D28: Mowaggep | E28: Sorikatul BMT | F28: Makkah Corporate | G28: 31 | H28: 0 | I28: =G28-H28 -> 31 | J28: =+M28/G28 -> 90.322581 | K28: 0 | L28: 6000 | M28: 2800 | N28: 0 | O28: 0 | P28: 0 | Q28: =J28/12*K28*1.5 -> 0 | R28: =SUM(M28:Q28) -> 2800 | S28: 0 | T28: =+H28*J28 -> 0 | U28: 0 | V28: 0 | W28: =SUM(S28:V28) -> 0 | X28: =+R28-W28-Z28 -> 0 | Y28: =L28-S28 -> 6000 | Z28: 2800
A29: 23 | B29: Neyamat Ullah | C29: 31.10.2024 | D29: Marketing Manager | E29: Under Kafala | F29: Makkah Corporate | G29: 31 | H29: 0 | I29: =G29-H29 -> 31 | J29: =+M29/G29 -> 80.645161 | K29: 0 | L29: 12000 | M29: 2500 | N29: 0 | O29: 0 | P29: 0 | Q29: =J29/12*K29*1.5 -> 0 | R29: =SUM(M29:Q29) -> 2500 | S29: 0 | T29: =+H29*J29 -> 0 | U29: 0 | V29: 0 | W29: =SUM(S29:V29) -> 0 | X29: =+R29-W29-Z29 -> 0 | Y29: =L29-S29 -> 12000 | Z29: 2500
A30: 24 | B30: Md Miraz Hossain | C30: 06.02.2025 | D30: Marketing Asst-M | E30: Under Kafala | F30: Makkah Corporate | G30: 31 | H30: 0 | I30: =G30-H30 -> 31 | J30: =+M30/G30 -> 70.967742 | K30: 0 | L30: 1600 | M30: 2200 | N30: 0 | O30: 0 | P30: 0 | Q30: =J30/12*K30*1.5 -> 0 | R30: =SUM(M30:Q30) -> 2200 | S30: 0 | T30: 0 | U30: 0 | V30: 0 | W30: =SUM(S30:V30) -> 0 | X30: =+R30-W30-Z30 -> 1800 | Y30: =L30-S30 -> 1600 | Z30: 400
A31: 26 | B31: Abdur Rahman | C31: 01.01.2025 | D31: Mowaggep | E31: Sorikatul BMT | F31: Makkah Corporate | G31: 31 | H31: 0 | I31: =G31-H31 -> 31 | J31: =+M31/G31 -> 80.645161 | K31: 0 | L31: 0 | M31: 2500 | N31: 0 | O31: 0 | P31: 0 | Q31: =J31/12*K31*1.5 -> 0 | R31: =SUM(M31:Q31) -> 2500 | S31: 0 | T31: =+H31*J31 -> 0 | U31: 0 | V31: 0 | W31: =SUM(S31:V31) -> 0 | X31: =+R31-W31-Z31 -> 0 | Y31: =L31-S31 -> 0 | Z31: 2500 | AA31: 10725
A32: 27 | B32: Md.Abu Saleh | C32: 02.03.2026 | D32: General Stuff | E32: Outside Kafala | F32: Makkah Corporate | G32: 31 | H32: 0 | I32: =G32-H32 -> 31 | J32: =+M32/G32 -> 80.645161 | K32: 0 | L32: 0 | M32: 2500 | N32: 0 | O32: 0 | P32: 0 | Q32: =J32/12*K32*1.5 -> 0 | R32: =SUM(M32:Q32) -> 2500 | S32: 0 | T32: =+H32*J32 -> 0 | U32: 0 | V32: 0 | W32: =SUM(S32:V32) -> 0 | X32: =+R32-W32-Z32 -> 2500 | Y32: =L32-S32 -> 0 | Z32: 0
A33: 29 | B33: Milon H M | C33: 01.01.2025 | D33: Manager | E33: Sorikatul BMT | F33: Makkah-01 | G33: 31 | H33: 15 | I33: =G33-H33 -> 16 | J33: =+M33/G33 -> 90.322581 | K33: 0 | L33: 0 | M33: 2800 | N33: 0 | O33: 0 | P33: 0 | Q33: =J33/12*K33*1.5 -> 0 | R33: =SUM(M33:Q33) -> 2800 | T33: =+H33*J33 -> 1354.8387 | U33: 0 | V33: 0 | W33: =SUM(S33:V33) -> 1354.8387 | X33: =+R33-W33-Z33 -> 1445.1613 | Y33: =L33-S33 -> 0 | Z33: 0
A34: 30 | B34: Md.Naim | C34: 01.02.2025 | D34: General STAFF | E34: Outside Kafala | F34: Makkah-01 | G34: 31 | H34: 0 | I34: =G34-H34 -> 31 | J34: =+M34/G34 -> 58.064516 | K34: 0 | L34: 5682 | M34: 1800 | N34: 0 | O34: 0 | P34: 0 | Q34: =J34/12*K34*1.5 -> 0 | R34: =SUM(M34:Q34) -> 1800 | S34: 300 | T34: =+H34*J34 -> 0 | U34: 0 | V34: 100 | W34: =SUM(S34:V34) -> 400 | X34: =+R34-W34-Z34 -> 1000 | Y34: =L34-S34 -> 5382 | Z34: 400
A35: 31 | B35: Shariful Islam | C35: 13.08.2025 | D35: Ticket STAFF | E35: Sorikatul BMT | F35: Makkah-02 | G35: 31 | H35: 0 | I35: =G35-H35 -> 31 | J35: =+M35/G35 -> 64.516129 | K35: 0 | L35: 1800 | M35: 2000 | N35: 0 | O35: 0 | P35: 0 | Q35: =J35/12*K35*1.5 -> 0 | R35: =SUM(M35:Q35) -> 2000 | S35: 0 | T35: =+H35*J35 -> 0 | U35: 0 | V35: 0 | W35: =SUM(S35:V35) -> 0 | X35: =+R35-W35-Z35 -> 1600 | Y35: =L35-S35 -> 1800 | Z35: 400
A36: 32 | B36: Md.Sumon Miah | C36: 14.07.25 | D36: General Staff | E36: Outside Kafala | F36: Makkah-02 | G36: 31 | H36: 0 | I36: =G36-H36 -> 31 | J36: =+M36/G36 -> 58.064516 | K36: 0 | L36: 0 | M36: 1800 | N36: 0 | O36: 0 | P36: 0 | Q36: =J36/12*K36*1.5 -> 0 | R36: =SUM(M36:Q36) -> 1800 | S36: 0 | T36: =+H36*J36 -> 0 | U36: 0 | V36: 0 | W36: =SUM(S36:V36) -> 0 | X36: =+R36-W36-Z36 -> 1400 | Y36: =L36-S36 -> 0 | Z36: 400
A37: 33 | B37: Golam Morshed | C37: 01.09.2025 | D37: General STAFF | E37: Outside Kafala | F37: Jubail | G37: 31 | H37: 0 | I37: =G37-H37 -> 31 | J37: =+M37/G37 -> 58.064516 | K37: 0 | L37: 3500 | M37: 1800 | N37: 0 | O37: 0 | P37: 0 | Q37: =J37/12*K37*1.5 -> 0 | R37: =SUM(M37:Q37) -> 1800 | S37: 1800 | T37: =+H37*J37 -> 0 | U37: 0 | V37: 0 | W37: =SUM(S37:V37) -> 1800 | X37: =+R37-W37-Z37 -> 0 | Y37: =L37-S37 -> 1700 | Z37: 0
A38: 34 | B38: Abdul Karim | C38: 24.02.2025 | D38: Manager | E38: Under Kafala | F38: Jubail | G38: 31 | H38: 0 | I38: =G38-H38 -> 31 | J38: =+M38/G38 -> 80.645161 | K38: 0 | L38: 0 | M38: 2500 | N38: 0 | O38: 0 | P38: 0 | Q38: =J38/12*K38*1.5 -> 0 | R38: =SUM(M38:Q38) -> 2500 | S38: 0 | T38: =+H38*J38 -> 0 | U38: 0 | V38: 0 | W38: =SUM(S38:V38) -> 0 | X38: =+R38-W38-Z38 -> 2500 | Y38: =L38-S38 -> 0 | Z38: 0 | AA38: 2000 Count as sep-25 salary
A39: 35 | B39: Ashraf Chowdhury | D39: General Staff | E39: Outside Kafala | F39: Jubail | G39: 31 | H39: 0 | I39: =G39-H39 -> 31 | J39: =+M39/G39 -> 61.290323 | K39: 0 | L39: 0 | M39: 1900 | N39: 0 | O39: 0 | P39: 0 | Q39: =J39/12*K39*1.5 -> 0 | R39: =SUM(M39:Q39) -> 1900 | S39: 0 | T39: =+H39*J39 -> 0 | U39: 0 | V39: 0 | W39: =SUM(S39:V39) -> 0 | X39: =+R39-W39-Z39 -> 1900 | Y39: =L39-S39 -> 0 | Z39: 0
A40: 36 | B40: Md Ismail Azum Rifat | C40: 01.01.2025 | D40: Ticket STAFF | E40: Sorikatul BMT | F40: Jubail | G40: 31 | H40: 0 | I40: =G40-H40 -> 31 | J40: =+M40/G40 -> 80.645161 | K40: 0 | L40: 12704 | M40: 2500 | N40: 0 | O40: 0 | P40: 0 | Q40: =J40/12*K40*1.5 -> 0 | R40: =SUM(M40:Q40) -> 2500 | S40: 2100 | T40: =+H40*J40 -> 0 | U40: 0 | V40: 0 | W40: =SUM(S40:V40) -> 2100 | X40: =+R40-W40-Z40 -> 0 | Y40: =L40-S40 -> 10604 | Z40: 400 | AA40: Akbar Alam=1092 & B2B=2887
A41: 37 | B41: Sohan Hosen | C41: 16.11.2024 | D41: Ticket STAFF | E41: Outside Kafala | F41: Jubail | G41: 31 | H41: 0 | I41: =G41-H41 -> 31 | J41: =+M41/G41 -> 96.774194 | K41: 0 | L41: 0 | M41: 3000 | N41: 0 | O41: 0 | P41: 0 | Q41: =J41/12*K41*1.5 -> 0 | R41: =SUM(M41:Q41) -> 3000 | S41: 0 | T41: =+H41*J41 -> 0 | U41: 0 | V41: 0 | W41: =SUM(S41:V41) -> 0 | X41: =+R41-W41-Z41 -> 3000 | Y41: =L41-S41 -> 0 | Z41: 0
...

Sheet Pay Slip
B2: BIN MISHAL GLOBAL SERVICE CO. LTD
B3: Salary Slip | D3: : | E3: {=XLOOKUP(C6,'Salary Sheet'!A6:A79,'Salary Sheet'!F6:F79,0)} -> Online
B4: ='Salary Sheet'!A2 -> Period : May''26
B6: Emmployee ID : | C6: 48 | E6: Employee Name: | F6: {=XLOOKUP(C6,'Salary Sheet'!A6:A83,'Salary Sheet'!B6:B83,0)} -> Arifur Rahman
B7: Designation: | C7: {=XLOOKUP(C6,'Salary Sheet'!A6:A83,'Salary Sheet'!D6:D83,0)} -> Manager | E7: Date of Payment: | F7: 46173
B8: Earnings | E8: Deduction
B9: Basic | C9: {=XLOOKUP(C6,'Salary Sheet'!A6:A79,'Salary Sheet'!M6:M79,0)} -> 2500 | E9: Loan Deduct | F9: {=XLOOKUP(C6,'Salary Sheet'!A6:A79,'Salary Sheet'!S6:S79,0)} -> 1000
B10: Breakfast | C10: {=XLOOKUP(C6,'Salary Sheet'!A6:A79,'Salary Sheet'!O6:O79,0)} -> 0 | E10: Iqama Cost | F10: {=XLOOKUP(C6,'Salary Sheet'!A6:A79,'Salary Sheet'!U6:U79,0)} -> 0
B11: Advance | C11: {=XLOOKUP(C6,'Salary Sheet'!A6:A79,'Salary Sheet'!N6:N79,0)} -> 0 | E11: Fine | F11: {=XLOOKUP(C6,'Salary Sheet'!A6:A79,'Salary Sheet'!V6:V79,0)} -> 0
B12: Over Time | C12: {=XLOOKUP(C6,'Salary Sheet'!A6:A79,'Salary Sheet'!Q6:Q79,0)} -> 0 | E12: Absent | F12: {=XLOOKUP(C6,'Salary Sheet'!A6:A79,'Salary Sheet'!T6:T79,0)} -> 0
B13: Commission | C13: {=XLOOKUP(C6,'Salary Sheet'!A6:A79,'Salary Sheet'!P6:P79,0)} -> 0 | E13: Paid by Bank | F13: {=XLOOKUP(C6,'Salary Sheet'!A6:A88,'Salary Sheet'!Z6:Z88,0)} -> 400
B14: Total Addition | C14: =SUM(C9:C13) -> 2500 | E14: Total Deduction | F14: =SUM(F9:F13) -> 1400
B16: Net Salary Payable : | C16: =C14-F14 -> 1100
B17: Salary in Words : | C17: =Moneytext(C16,"SAR")& " riyal" -> One thousand one hundred riyal
B18: Remaining Loan (IF) : | C18: {=XLOOKUP(C6,'Salary Sheet'!A6:A79,'Salary Sheet'!Y6:Y79,0)} -> 5500 | D18: =Moneytext(C18,"SAR")& " riyal" -> Five thousand five hundred riyal
B20: Paid By Cash : | C20: TRUE
B21: Paid By Bank : | C21: FALSE
B26: Branch Manager | C26: Payment By | E26: Accounts | F26: Employee Sign

Sheet Copy of Pay Slip
B2: BIN MISHAL GLOBAL SERVICE CO. LTD
B3: Salary Slip | D3: : | E3: {=XLOOKUP(C6,'Salary Sheet'!A6:A79,'Salary Sheet'!F6:F79,0)} -> Makkah-02
B4: ='Salary Sheet'!A2 -> Period : May''26
B6: Emmployee ID : | C6: 32 | E6: Employee Name: | F6: {=XLOOKUP(C6,'Salary Sheet'!A6:A83,'Salary Sheet'!B6:B83,0)} -> Md.Sumon Miah
B7: Designation: | C7: {=XLOOKUP(C6,'Salary Sheet'!A6:A83,'Salary Sheet'!D6:D83,0)} -> General Staff | E7: Date of Payment: | F7: 46173
B8: Earnings | E8: Deduction
B9: Basic | C9: {=XLOOKUP(C6,'Salary Sheet'!A6:A79,'Salary Sheet'!M6:M79,0)} -> 1800 | E9: Loan Deduct | F9: {=XLOOKUP(C6,'Salary Sheet'!A6:A79,'Salary Sheet'!S6:S79,0)} -> 0
B10: Breakfast | C10: {=XLOOKUP(C6,'Salary Sheet'!A6:A79,'Salary Sheet'!O6:O79,0)} -> 0 | E10: Iqama Cost | F10: {=XLOOKUP(C6,'Salary Sheet'!A6:A79,'Salary Sheet'!U6:U79,0)} -> 0
B11: Advance | C11: 0 | E11: Fine | F11: {=XLOOKUP(C6,'Salary Sheet'!A6:A79,'Salary Sheet'!V6:V79,0)} -> 0
B12: Over Time | C12: {=XLOOKUP(C6,'Salary Sheet'!A6:A79,'Salary Sheet'!Q6:Q79,0)} -> 0 | E12: Absent | F12: {=XLOOKUP(C6,'Salary Sheet'!A6:A79,'Salary Sheet'!T6:T79,0)} -> 0
B13: Commission | C13: {=XLOOKUP(C6,'Salary Sheet'!A6:A79,'Salary Sheet'!P6:P79,0)} -> 0 | E13: Paid by Bank | F13: {=XLOOKUP(C6,'Salary Sheet'!A6:A88,'Salary Sheet'!Z6:Z88,0)} -> 400
B14: Total Addition | C14: =SUM(C9:C13) -> 1800 | E14: Total Deduction | F14: =SUM(F9:F13) -> 400
B16: Net Salary Payable : | C16: =C14-F14 -> 1400
B17: Salary in Words : | C17: =Moneytext(C16,"SAR")& " riyal" -> One thousand four hundred riyal
B18: Remaining Loan (IF) : | C18: {=XLOOKUP(C6,'Salary Sheet'!A6:A79,'Salary Sheet'!Y6:Y79,0)} -> 0 | D18: =Moneytext(C18,"SAR")& " riyal" -> Zero riyal
B20: Paid By Cash : | C20: TRUE
B21: Paid By Bank : | C21: FALSE
B23: Notice: This wages paid for month of May-2026 with mutual termination.
B26: Branch Manager | C26: Payment By | E26: Accounts | F26: Employee Sign
